<robot name = "robot">
    <link name="Link0">
        <inertial>
            <origin xyz="0 0 1" rpy="0 0 0"/>
            <mass value="1" />
            <inertia ixx="100" ixy="0" ixz="0" iyy="100" iyz="0" izz="100" />
        </inertial>
        <visual>
            <origin xyz="0 0 1" rpy="0 0 0"/>
            <geometry>
                <box size="0.03673619997716404 0.41113029052463546 2" />
            </geometry>
            <material name="Green">
                <color rgba="0 1 0 1"/>
            </material>
        </visual>
        <collision>
            <origin xyz="0 0 1" rpy="0 0 0"/>
            <geometry>
                <box size="0.03673619997716404 0.41113029052463546 2" />
            </geometry>
        </collision>
    </link>
    <link name="Link1">
        <inertial>
            <origin xyz="0.43177265080722294 0 0" rpy="0 0 0"/>
            <mass value="1" />
            <inertia ixx="100" ixy="0" ixz="0" iyy="100" iyz="0" izz="100" />
        </inertial>
        <visual>
            <origin xyz="0.43177265080722294 0 0" rpy="0 0 0"/>
            <geometry>
                <box size="0.8635453016144459 0.5143596462778961 0.13089836352824924" />
            </geometry>
            <material name="Green">
                <color rgba="0 1 0 1"/>
            </material>
        </visual>
        <collision>
            <origin xyz="0.43177265080722294 0 0" rpy="0 0 0"/>
            <geometry>
                <box size="0.8635453016144459 0.5143596462778961 0.13089836352824924" />
            </geometry>
        </collision>
    </link>
    <link name="Link2">
        <inertial>
            <origin xyz="0.1858121648651614 0 0" rpy="0 0 0"/>
            <mass value="1" />
            <inertia ixx="100" ixy="0" ixz="0" iyy="100" iyz="0" izz="100" />
        </inertial>
        <visual>
            <origin xyz="0.1858121648651614 0 0" rpy="0 0 0"/>
            <geometry>
                <box size="0.3716243297303228 0.6663487557258075 0.13089836352824924" />
            </geometry>
            <material name="Cyan">
                <color rgba="0 0 1 1"/>
            </material>
        </visual>
        <collision>
            <origin xyz="0.1858121648651614 0 0" rpy="0 0 0"/>
            <geometry>
                <box size="0.3716243297303228 0.6663487557258075 0.13089836352824924" />
            </geometry>
        </collision>
    </link>
    <link name="Link3">
        <inertial>
            <origin xyz="0.21833578659422453 0 0" rpy="0 0 0"/>
            <mass value="1" />
            <inertia ixx="100" ixy="0" ixz="0" iyy="100" iyz="0" izz="100" />
        </inertial>
        <visual>
            <origin xyz="0.21833578659422453 0 0" rpy="0 0 0"/>
            <geometry>
                <box size="0.43667157318844907 0.9269817520927305 0.13089836352824924" />
            </geometry>
            <material name="Cyan">
                <color rgba="0 0 1 1"/>
            </material>
        </visual>
        <collision>
            <origin xyz="0.21833578659422453 0 0" rpy="0 0 0"/>
            <geometry>
                <box size="0.43667157318844907 0.9269817520927305 0.13089836352824924" />
            </geometry>
        </collision>
    </link>
    <joint name="Link0_Link1" type="revolute">
       <parent link="Link0"/>
       <child  link="Link1"/>
       <origin rpy="0 0 0" xyz="0.01836809998858202 0 1" />
       <axis xyz="0 0 1"/>
       <limit effort="0.0" lower="-3.14159" upper="3.14159" velocity="0.0"/>
    </joint>
    <joint name="Link1_Link2" type="revolute">
       <parent link="Link1"/>
       <child  link="Link2"/>
       <origin rpy="0 0 0" xyz="0.8635453016144459 0 0" />
       <axis xyz="0 0 1"/>
       <limit effort="0.0" lower="-3.14159" upper="3.14159" velocity="0.0"/>
    </joint>
    <joint name="Link2_Link3" type="revolute">
       <parent link="Link2"/>
       <child  link="Link3"/>
       <origin rpy="0 0 0" xyz="0.3716243297303228 0 0" />
       <axis xyz="0 0 1"/>
       <limit effort="0.0" lower="-3.14159" upper="3.14159" velocity="0.0"/>
    </joint>
</robot>